<?xml version="1.0"?>
<robot name="fang">

<material name="blue">
    <color rgba="0 0 2 1"/>
  </material>
  <material name="red">
    <color rgba="1 0 0 1"/>
  </material>
  <material name="white">
    <color rgba="1 1 1 0.5"/>
  </material>

<link name="base_link">
</link>

<joint name="base_joint" type="fixed">
    <parent link="base_link"/>
    <child link="link_0"/>
    <origin xyz="0.0 0.3 0.6"/>
</joint>

  <link name="link_0">
    <visual>
      <geometry>
        <box size="0.9 1 1"/>
      </geometry>
      <origin rpy="0 0 0" xyz="0 0 0"/>
      <material name="white"/>
    </visual>
  </link>

  <joint name="joint_0" type="revolute">
    <parent link="link_0"/>
    <child link="link_1"/>
    <origin xyz="0 0 0"/>
    <axis xyz="0 0 1"/>
   <limit effort="30" velocity="1.0" lower="-1" upper="1" />
  </joint>

  <link name="link_1">
    <visual>
      <origin xyz="0 0 1" rpy="0 0 0" />
      <geometry>
        <cylinder length="1.5" radius="0.4"/>
      </geometry>
      <material name="red"/>
    </visual>
  </link>

  <joint name="joint_1" type="revolute">
    <parent link="link_1"/>
    <child link="link_2"/>
    <origin xyz="0.03 0.0 0.1"/>
    <axis xyz="0 1 0"/>
    <limit effort="30" velocity="1.0" lower="-1" upper="1" />
  </joint>

  <link name="link_2">
    <visual>
      <geometry>
        <box size="0.6 1.7 0.8"/>
      </geometry>
      <origin rpy="0 0.7 0" xyz="0 0 1.5"/>
      <material name="blue"/>
    </visual>
  </link>

<joint name="joint_2" type="revolute">
    <parent link="link_2"/>
    <child link="link_3"/>
    <origin xyz="0.0 0 0"/>
    <axis xyz="0 0 1.1"/>
    <limit effort="30" velocity="1.0" lower="-1" upper="1" />
  </joint>


  <link name="link_3">
    <visual>
      <geometry>
        <box size="1 0.7 0.6"/>
      </geometry>
      <origin rpy="0 0 0" xyz="0 0 1.5"/>
      <material name="red"/>
    </visual>
  </link>
-->
 
</robot>
